#VRML_SIM R2025a utf8

EXTERNPROTO "https://raw.githubusercontent.com/cyberbotics/webots/R2023b/projects/objects/backgrounds/protos/TexturedBackground.proto"
EXTERNPROTO "https://raw.githubusercontent.com/cyberbotics/webots/R2023b/projects/objects/backgrounds/protos/TexturedBackgroundLight.proto"
EXTERNPROTO "https://raw.githubusercontent.com/cyberbotics/webots/R2023b/projects/objects/floors/protos/Floor.proto"

WorldInfo {
  basicTimeStep 16
}
Viewpoint {
  orientation 0.2601593616689325 -0.35568075742214544 -0.8976682601805761 4.990345913735541
  position -1.48477873463312 -3.2235925814921416 2.3298270120696136
}
TexturedBackground {
}
TexturedBackgroundLight {
}
Floor {
  translation 1 1 0
  size 2 3
}
DEF WALL_1 Solid {
  translation 0 0 0.05
  children [
    DEF WALL_SHAPE Shape {
      appearance PBRAppearance {
        baseColor 0.12549 0.368627 0.729412
        roughness 1
        metalness 0
      }
      geometry Box {
        size 0.02 1 0.1
      }
    }
  ]
  boundingObject USE WALL_SHAPE
}
DEF WALL_2 Solid {
  translation 0 1 0.05
  children [
    USE WALL_SHAPE
  ]
  name "solid(2)"
  boundingObject USE WALL_SHAPE
}
DEF WALL_3 Solid {
  translation 0 2 0.05
  children [
    USE WALL_SHAPE
  ]
  name "solid(3)"
  boundingObject USE WALL_SHAPE
}
DEF WALL_4 Solid {
  translation 0.5 -0.5 0.05
  rotation 0 0 1 1.5708
  children [
    USE WALL_SHAPE
  ]
  name "solid(4)"
  boundingObject USE WALL_SHAPE
}
DEF WALL_5 Solid {
  translation 0.5 2.5 0.05
  rotation 0 0 1 1.5708
  children [
    USE WALL_SHAPE
  ]
  name "solid(5)"
  boundingObject USE WALL_SHAPE
}
DEF WALL_6 Solid {
  translation 1 0 0.05
  children [
    USE WALL_SHAPE
  ]
  name "solid(6)"
  boundingObject USE WALL_SHAPE
}
DEF WALL_7 Solid {
  translation 1 1 0.05
  children [
    USE WALL_SHAPE
  ]
  name "solid(7)"
  boundingObject USE WALL_SHAPE
}
DEF WALL_8 Solid {
  translation 1.5 -0.5 0.05
  rotation 0 0 1 1.5708
  children [
    USE WALL_SHAPE
  ]
  name "solid(8)"
  boundingObject USE WALL_SHAPE
}
DEF WALL_9 Solid {
  translation 1.5 2.5 0.05
  rotation 0 0 1 1.5708
  children [
    USE WALL_SHAPE
  ]
  name "solid(9)"
  boundingObject USE WALL_SHAPE
}
DEF WALL_10 Solid {
  translation 2 0 0.05
  children [
    USE WALL_SHAPE
  ]
  name "solid(10)"
  boundingObject USE WALL_SHAPE
}
DEF WALL_11 Solid {
  translation 2 1 0.05
  children [
    USE WALL_SHAPE
  ]
  name "solid(11)"
  boundingObject USE WALL_SHAPE
}
DEF WALL_12 Solid {
  translation 2 2 0.05
  children [
    USE WALL_SHAPE
  ]
  name "solid(12)"
  boundingObject USE WALL_SHAPE
}
DEF CYLINDER Pose {
  translation 1.5 0 0.2
  children [
    Shape {
      appearance PBRAppearance {
        baseColor 0.5 0 0
        roughness 0.2
        metalness 0
      }
      geometry Cylinder {
        height 0.4
        radius 0.1
      }
    }
  ]
}
DEF CONE Pose {
  translation 1.5 0 0.4
  children [
    Shape {
      appearance PBRAppearance {
        baseColor 0.5 0 0
        roughness 0.2
        metalness 0
      }
      geometry Cone {
        bottomRadius 0.2
        height 0.2
        subdivision 36
      }
    }
  ]
}
Robot {
  translation 0.49999999339568557 -2.2061356291064713e-08 0.03986048964923723
  rotation -8.73256769452922e-09 -8.73260370802431e-09 1 1.570799999999498
  children [
    DEF BODY Shape {
      appearance PBRAppearance {
        baseColor 0.917647 0.145098 0.145098
        roughness 1
        metalness 0
      }
      geometry Box {
        size 0.2 0.1 0.05
      }
    }
    DEF WHEEL1 HingeJoint {
      jointParameters HingeJointParameters {
        position 707.9180850044874
        axis 0 1 0
        anchor 0.05 0.06 0
      }
      device [
        RotationalMotor {
          name "wheel1"
        }
      ]
      endPoint Solid {
        translation 0.05 0.06 0
        rotation -0.3826587054780406 0.6532875246687675 -0.6532899243322405 3.8725265764928767
        children [
          DEF WHEEL Shape {
            appearance PBRAppearance {
              baseColor 0.305882 0.898039 0.25098
              roughness 1
              metalness 0
            }
            geometry Cylinder {
              height 0.02
              radius 0.04
              subdivision 24
            }
          }
        ]
        boundingObject USE WHEEL
        physics Physics {
        }
        linearVelocity 3.615956098925274e-14 3.297978485079991e-13 7.421278215326931e-16
        angularVelocity -9.079779666473366e-12 -6.318467613033572e-15 -1.7230126850397995e-12
      }
    }
    DEF WHEEL2 HingeJoint {
      jointParameters HingeJointParameters {
        position 319.8948711343375
        axis 0 1 0
        anchor 0.05 -0.06 0
      }
      device [
        RotationalMotor {
          name "wheel2"
        }
      ]
      endPoint Solid {
        translation 0.05 -0.06 0
        rotation -0.9293807046791976 0.2610086256144346 -0.26100958435441024 4.639213874991992
        children [
          USE WHEEL
        ]
        name "solid(1)"
        boundingObject USE WHEEL
        physics Physics {
        }
        linearVelocity 3.694188080830006e-14 3.2959413519001905e-14 4.947539453131117e-16
        angularVelocity 1.0265150608653368e-14 3.822733536134286e-15 -1.7220674436345123e-12
      }
    }
    DEF WHEEL3 HingeJoint {
      jointParameters HingeJointParameters {
        position 707.9181083650051
        axis 0 1 0
        anchor -0.05 0.06 0
      }
      device [
        RotationalMotor {
          name "wheel3"
        }
      ]
      endPoint Solid {
        translation -0.05 0.06 0
        rotation -0.3826674534040752 0.6532849626249059 -0.6532873622789709 3.8725418375977556
        children [
          USE WHEEL
        ]
        name "solid(2)"
        boundingObject USE WHEEL
        physics Physics {
        }
        linearVelocity -3.637501693444746e-14 3.2979357755164115e-13 -6.361108797151238e-16
        angularVelocity -9.07962743973732e-12 5.2835265547311845e-17 -1.7218703875453336e-12
      }
    }
    DEF WHEEL4 HingeJoint {
      jointParameters HingeJointParameters {
        position 319.8948943148472
        axis 0 1 0
        anchor -0.05 -0.06 0
      }
      device [
        RotationalMotor {
          name "wheel4"
        }
      ]
      endPoint Solid {
        translation -0.05 -0.06 0
        rotation -0.929386342718994 0.2609985876649344 -0.2609995463680387 4.639219925188628
        children [
          USE WHEEL
        ]
        name "solid(3)"
        boundingObject USE WHEEL
        physics Physics {
        }
        linearVelocity -3.7131497461363386e-14 3.296283191020568e-14 -7.77467491814887e-16
        angularVelocity 1.0191585314515379e-14 -8.919873016050272e-15 -1.7241417092776607e-12
      }
    }
    DEF DS_RIGHT DistanceSensor {
      translation 0.1 -0.03 0
      children [
        Shape {
          appearance PBRAppearance {
            baseColor 0.184314 0.596078 0.847059
            roughness 1
            metalness 0
          }
          geometry Box {
            size 0.01 0.01 0.01
          }
        }
      ]
      name "ds_right"
      lookupTable [
        0 0 0
        4 400 0
      ]
      type "sonar"
    }
    DEF DS_LEFT DistanceSensor {
      translation 0.1 0.03 0
      children [
        Shape {
          appearance PBRAppearance {
            baseColor 0.184314 0.596078 0.847059
            roughness 1
            metalness 0
          }
          geometry Box {
            size 0.01 0.01 0.01
          }
        }
      ]
      name "ds_left"
      lookupTable [
        0 0 0
        4 400 0
      ]
      type "sonar"
    }
    DEF ROBOT_GPS GPS {
      name "robot_gps"
    }
  ]
  boundingObject USE BODY
  physics Physics {
    density -1
    mass 1
  }
  controller "four_wheels_collision_avoidance"  
  linearVelocity -7.950333166102637e-16 1.8135008192189578e-13 -2.842170943040401e-17
  angularVelocity 1.3291326821218412e-14 -1.2790940966441428e-15 -1.7252140485392586e-12
}
